function timeout(ms: number) {
  return new Promise((resolve) => setTimeout(resolve, ms));
}

export default async function retryable(
  fn: () => Promise<void>,
  interval: number,
  maxTimeout: number,
) {
  if (maxTimeout < 0) throw new Error('never');
  const end = Date.now() + maxTimeout;
  let lastError: Error = new Error('never');
  let n = 0;
  while (Date.now() < end) {
    try {
      await fn();
      console.info(`Succeeded on the ${++n} time.`);
      return;
    } catch (e) {
      console.info(`${++n} times tried. Retrying...`);
      lastError = e;
      await timeout(interval);
    }
  }
  throw lastError;
}
